Workbook
Name ListStores: 'Dropdown List'!$A$2:$A$12
Name ListZones: 'Dropdown List'!$D$2:$D$1414
Name ListAreas: 'Dropdown List'!$I$2:$I$1771

Sheet Worksheet
A1: ItemType | B1: StoreName | C1: MerchantOrderId | D1: RecipientName(*) | E1: RecipientPhone(*) | F1: RecipientCity(*) | G1: RecipientZone(*) | H1: RecipientArea | I1: RecipientAddress(*) | J1: AmountToCollect(*) | K1: ItemQuantity | L1: ItemWeight | M1: ItemDesc | N1: SpecialInstruction
A2: package | C2: 487057 | D2: Mr Xyz | E2: 9802370672 | F2: =IFERROR(VLOOKUP(VLOOKUP(G2,'Dropdown List'!$D:$F,2,FALSE),'Dropdown List'!$B:$C,2, FALSE), "") -> 0 | G2: Kalimati | I2: Flat-6,House-1,Road-1 | J2: 1000 | K2: 1 | L2: 0.5
F3: =IFERROR(VLOOKUP(VLOOKUP(G3,'Dropdown List'!$D:$F,2,FALSE),'Dropdown List'!$B:$C,2, FALSE), "") -> 0
F4: =IFERROR(VLOOKUP(VLOOKUP(G4,'Dropdown List'!$D:$F,2,FALSE),'Dropdown List'!$B:$C,2, FALSE), "") -> 0
F5: =IFERROR(VLOOKUP(VLOOKUP(G5,'Dropdown List'!$D:$F,2,FALSE),'Dropdown List'!$B:$C,2, FALSE), "") -> 0
F6: =IFERROR(VLOOKUP(VLOOKUP(G6,'Dropdown List'!$D:$F,2,FALSE),'Dropdown List'!$B:$C,2, FALSE), "") -> 0
F7: =IFERROR(VLOOKUP(VLOOKUP(G7,'Dropdown List'!$D:$F,2,FALSE),'Dropdown List'!$B:$C,2, FALSE), "") -> 0
F8: =IFERROR(VLOOKUP(VLOOKUP(G8,'Dropdown List'!$D:$F,2,FALSE),'Dropdown List'!$B:$C,2, FALSE), "") -> 0
F9: =IFERROR(VLOOKUP(VLOOKUP(G9,'Dropdown List'!$D:$F,2,FALSE),'Dropdown List'!$B:$C,2, FALSE), "") -> 0
F10: =IFERROR(VLOOKUP(VLOOKUP(G10,'Dropdown List'!$D:$F,2,FALSE),'Dropdown List'!$B:$C,2, FALSE), "") -> 0
F11: =IFERROR(VLOOKUP(VLOOKUP(G11,'Dropdown List'!$D:$F,2,FALSE),'Dropdown List'!$B:$C,2, FALSE), "") -> 0
F12: =IFERROR(VLOOKUP(VLOOKUP(G12,'Dropdown List'!$D:$F,2,FALSE),'Dropdown List'!$B:$C,2, FALSE), "") -> 0
F13: =IFERROR(VLOOKUP(VLOOKUP(G13,'Dropdown List'!$D:$F,2,FALSE),'Dropdown List'!$B:$C,2, FALSE), "") -> 0
F14: =IFERROR(VLOOKUP(VLOOKUP(G14,'Dropdown List'!$D:$F,2,FALSE),'Dropdown List'!$B:$C,2, FALSE), "") -> 0
... F100: =IFERROR(VLOOKUP(VLOOKUP(G100,'Dropdown List'!$D:$F,2,FALSE),'Dropdown List'!$B:$C,2, FALSE), "") -> 0

Sheet Dropdown List
A1: store | B1: city_id | C1: city_name | D1: zone_name | E1: zone_city_id | F1: zone_id | G1: area_id | H1: area_zone_id | I1: area_name
A2: Yachu Jorpati | B2: 65 | C2: Kathmandu Valley | D2: Odari (Kapilvastu) | E2: 98 | F2: 482 | G2: 3424 | H2: 482 | I2: Odari (Kapilvastu)
A3: Yachu Gairidhara | B3: 66 | C3: Budar (Doti) | D3: Labani (Rupandehi) | E3: 98 | F3: 483 | G3: 3425 | H3: 483 | I3: Labani (Rupandehi)
A4: Yachu Kritipur | B4: 67 | C4: Bodebarsain (Saptari) | D4: Ganeshpur (Kapilvastu) | E4: 98 | F4: 484 | G4: 3426 | H4: 484 | I4: Ganeshpur (Kapilvastu)
A5: Yachu Baliyo ventures Pvt.Ltd | B5: 68 | C5: Udayapur | D5: Baidauli (Kapilvastu) | E5: 98 | F5: 485 | G5: 3427 | H5: 485 | I5: Baidauli (Kapilvastu)
A6: Yachu Bhaktapur | B6: 69 | C6: Bidur (Nuwakot) | D6: Duduwa (Banke) | E6: 173 | F6: 486 | G6: 3428 | H6: 486 | I6: Duduwa (Banke)
A7: Yachu Jhamsikhel | B7: 70 | C7: Phungling (Taplejung) | D7: Kageshwari Manohara | E7: 65 | F7: 487 | G7: 3429 | H7: 487 | I7: Kageshwari Manohara
A8: New Uttam Traders | B8: 71 | C8: Battar Bazar (Nuwakot) | D8: Gerkhutar (Nuwakot) | E8: 102 | F8: 488 | G8: 3430 | H8: 1312 | I8: Kritipur
A9: Yachu Soalteemode | B9: 75 | C9: Galyang (Syangja) | D9: Piprahawa (Banke) | E9: 143 | F9: 489 | G9: 3431 | H9: 489 | I9: Piprahawa (Banke)
A10: Yachu Lagankhel | B10: 76 | C10: Nagarkot | D10: Jeetpur Char Number (Kapilvastu) | E10: 98 | F10: 490 | G10: 3432 | H10: 490 | I10: Jeetpur Char Number (Kapilvastu)
A11: Yachu Sitapaila | B11: 77 | C11: Pharping | D11: Sukhipur (Lahan) | E11: 216 | F11: 491 | G11: 22839 | H11: 1200 | I11: Anamnagar
A12: Yachu Baneshwor | B12: 79 | C12: Lakeside (Pokhara) | D12: Anamnagar | E12: 65 | F12: 1200 | G12: 22840 | H12: 1201 | I12: Bagbazar
B13: 80 | C13: Bhairahawa | D13: Bagbazar | E13: 65 | F13: 1201 | G13: 22841 | H13: 1202 | I13: Plan International Nepal, Country Office
B14: 81 | C14: Sainamaina (Rupandehi) | D14: Bakhundol | E14: 65 | F14: 1202 | G14: 22842 | H14: 1202 | I14: Shangrila Blu Hotel
B15: 83 | C15: Hatkhola (Biratnagar) | D15: Balaju | E15: 65 | F15: 1203 | G15: 22843 | H15: 1202 | I15: Embassy of Norway
B16: 84 | C16: Itahari | D16: Balkhu | E16: 65 | F16: 1204 | G16: 22844 | H16: 1202 | I16: KORA Creations
B17: 85 | C17: Birtamod | D17: Baluwatar | E17: 65 | F17: 1205 | G17: 22845 | H17: 1202 | I17: Koshi Book Store
B18: 86 | C18: Hetauda | D18: Banasthali | E18: 65 | F18: 1206 | G18: 22846 | H18: 1202 | I18: Maxims Banquet
B19: 87 | C19: Khajura (Nepalgunj) | D19: Basundhara | E19: 65 | F19: 1207 | G19: 22847 | H19: 1203 | I19: Balaju Park
B20: 88 | C20: Kerkha (Damak) | D20: Battishputali | E20: 65 | F20: 1208 | G20: 22848 | H20: 1203 | I20: Manakamana Mandir Kathmandu
B21: 90 | C21: Shuklagandaki (Tanhau) | D21: Bhaisepati | E21: 65 | F21: 1209 | G21: 22849 | H21: 1203 | I21: Himalayan Yoga Academy
B22: 91 | C22: Lalgadh (Bardibas) | D22: Bhanimandal Chowk | E22: 65 | F22: 1210 | G22: 22850 | H22: 1203 | I22: Balaju Bypass
B23: 92 | C23: Janakpur (Mahendranagar) | D23: Bhimsengola | E23: 65 | F23: 1211 | G23: 22851 | H23: 1203 | I23: Bohoratar
B24: 93 | C24: Dhangadhi | D24: Boudhha | E24: 65 | F24: 1212 | G24: 22852 | H24: 1203 | I24: Bhat-Bhateni Store Balaju
... B317: 448 | C317: Balara | D317: Shivgunj (Jhapa) | E317: 258 | F317: 1636 | G317: 23146 | H317: 1291 | I317: The British College, Kathmandu
D318: Baletaxar (Gulmi) | E318: 117 | F318: 1637 | G318: 23147 | H318: 1292 | I318: Koteshwor Multiple Campus Area
D319: Ratuwamai (Sombare) | E319: 179 | F319: 1638 | G319: 23148 | H319: 1292 | I319: You Tv Nepal
D320: Chakrapath | E320: 65 | F320: 1639 | G320: 23149 | H320: 1292 | I320: Hamro Sahayatri Hospital And Birthing Centre
D321: Kadaghari | E321: 65 | F321: 1640 | G321: 23150 | H321: 1292 | I321: Puspanjali Cinema Hall
D322: Naikap | E322: 65 | F322: 1641 | G322: 23151 | H322: 1292 | I322: Jadibuti Bus And Micro Stand
D323: Lamatar | E323: 65 | F323: 1642 | G323: 23152 | H323: 1293 | I323: Jagati Bus Stand
D324: Chardobato | E324: 65 | F324: 1643 | G324: 23153 | H324: 1293 | I324: Jagati Police Station Area
D325: Narayantar | E325: 65 | F325: 1644 | G325: 23154 | H325: 1293 | I325: Doleshwor Chok
D326: Mhepi | E326: 65 | F326: 1645 | G326: 23155 | H326: 1294 | I326: Radhe Radhe Bus Station
D327: Jarankhu | E327: 65 | F327: 1646 | G327: 23156 | H327: 1294 | I327: Bhatbhatni Super Market
D328: Aarubari | E328: 65 | F328: 1647 | G328: 23157 | H328: 1295 | I328: Tuinkune Sallaghari Area
D329: Khusibu | E329: 65 | F329: 1648 | G329: 23158 | H329: 1295 | I329: Nepal Sbi Bank Ltd
... D1414: DHURA BAZAR | E1414: 112 | F1414: 3118 | G1414: 35349 | H1414: 2566 | I1414: Maitrinagar
G1415: 35350 | H1415: 2567 | I1415: Medicity Hospital
G1416: 35351 | H1416: 2568 | I1416: Mitranagar
...
